<?xml version="1.0"?>
<robot xmlns:xacro="http://www.ros.org/wiki/xacro" xmlns:ode="http://www.ros.org/wiki/xacro">

    <material name = "white">
        <color rgba="1 1 1 1"/>
    </material>

    <material name = "orange">
        <color rgba="1 0.647 0 1"/>
    </material>

    <material name = "blue">
        <color rgba="0 0 1 1"/>
    </material>

    <material name = "black">
        <color rgba="0 0 0 1"/>
    </material>

    <material name = "red">
        <color rgba="1 0 0 1"/>
    </material>

    <link name="base_link">

    </link>

    <joint name="base_footprint_joint" type="fixed">
        <parent link="base_link"/>
        <child link="base_footprint"/>
        <origin xyz="0 0 0" rpy="0 0 0"/>
    </joint>

    <link name="base_footprint">
    </link>

    <joint name="chasis_joint" type="fixed">
        <parent link="base_link"/>
        <child link="chassis"/>
        <origin xyz="-0.1 0 0" />
    </joint>

    <link name="chassis">
        <visual>
            <origin xyz="0.15 0 0.075" rpy="0 0 0"/>
            <geometry>
                <box size="0.3 0.3 0.15"/>
            </geometry>
            <material name="white"/>
        </visual>
        <collision>
            <origin xyz="0.15 0 0.075" rpy="0 0 0"/>
            <geometry>
                <box size="0.3 0.3 0.15"/>
            </geometry>
        </collision>
        <inertial>
            <mass value="0.5"/>
            <origin xyz="0.15 0 0.075" rpy="0 0 0"/>
            <inertia ixx="0.01" ixy="0.0" ixz="0.0" iyy="0.01" iyz="0.0" izz="0.01"/>
        </inertial>
    </link>

    <gazebo reference="chassis">
        <material>Gazebo/White</material>
    </gazebo>

    <joint name="left_wheel_joint" type="continuous">
        <parent link="base_link"/>
        <child link="left_wheel"/>
        <origin xyz="0 0.175 0" rpy="-${pi/2} 0 0"/>
        <axis xyz="0 0 1"/>
    </joint>

    <gazebo reference="left_wheel_joint">
        <joint_properties>
            <ode:ode>
                <fudge_factor>0.1</fudge_factor>
            </ode:ode>
        </joint_properties>
    </gazebo>

    <transmission name="left_wheel_joint_trans">
        <type>transmission_interface/SimpleTransmission</type>
        <joint name="left_wheel_joint">
            <hardwareInterface>hardware_interface/VelocityJointInterface</hardwareInterface>
        </joint>
        <actuator name="left_wheel_motor">
            <hardwareInterface>hardware_interface/VelocityJointInterface</hardwareInterface>
            <mechanicalReduction>1</mechanicalReduction>
        </actuator>
    </transmission>

    <link name="left_wheel">
        <visual>
            <origin xyz="0 0 0" rpy="0 0 0"/>
            <geometry>
                <cylinder length="0.04" radius="0.05"/>
            </geometry>
            <material name="blue"/>
        </visual>
        <collision>
            <origin xyz="0 0 0" rpy="0 0 0"/>
            <geometry>
                <cylinder length="0.04" radius="0.05"/>
            </geometry>
        </collision>
        <inertial>
            <mass value="0.1"/>
            <origin xyz="0 0 0" rpy="0 0 0"/>
            <inertia ixx="0.001" ixy="0.0" ixz="0.0" iyy="0.001" iyz="0.0" izz="0.001"/>
        </inertial>
    </link>

    <gazebo reference="left_wheel">
        <material>Gazebo/Blue</material>
    </gazebo>

    <joint name="right_wheel_joint" type="continuous">
        <parent link="base_link"/>
        <child link="right_wheel"/>
        <origin xyz="0 -0.175 0" rpy="${pi/2} 0 0"/>
        <axis xyz="0 0 -1"/>
    </joint>

    <gazebo reference="right_wheel_joint">
        <joint_properties>
            <ode:ode>
                <fudge_factor>0.1</fudge_factor>
            </ode:ode>
        </joint_properties>
    </gazebo>

    <transmission name="right_wheel_joint_trans">
        <type>transmission_interface/SimpleTransmission</type>
        <joint name="right_wheel_joint">
            <hardwareInterface>hardware_interface/VelocityJointInterface</hardwareInterface>
        </joint>
        <actuator name="right_wheel_motor">
            <hardwareInterface>hardware_interface/VelocityJointInterface</hardwareInterface>
            <mechanicalReduction>1</mechanicalReduction>
        </actuator>
    </transmission>

    <link name="right_wheel">
        <visual>
            <origin xyz="0 0 0" rpy="0 0 0"/>
            <geometry>
                <cylinder length="0.04" radius="0.05"/>
            </geometry>
            <material name="blue"/>
        </visual>
        <collision>
            <origin xyz="0 0 0" rpy="0 0 0"/>
            <geometry>
                <cylinder length="0.04" radius="0.05"/>
            </geometry>
        </collision>
        <inertial>
            <mass value="0.1"/>
            <origin xyz="0 0 0" rpy="0 0 0"/>
            <inertia ixx="0.001" ixy="0.0" ixz="0.0" iyy="0.001" iyz="0.0" izz="0.001"/>
        </inertial>
    </link>

    <gazebo reference="right_wheel">
        <material>Gazebo/Blue</material>
    </gazebo>

    <joint name="caster_wheel_joint" type="fixed">
        <parent link="chassis"/>
        <child link="caster_wheel"/>
        <origin xyz="0.24 0 0"/>
    </joint>

    <link name="caster_wheel">
        <visual>
            <geometry>
                <sphere radius="0.05"/>
            </geometry>
            <material name="black"/>
        </visual>
        <collision>
            <geometry>
                <sphere radius="0.05"/>
            </geometry>
        </collision>
        <inertial>
            <mass value="0.1"/>
            <origin xyz="0 0 0" rpy="0 0 0"/>
            <inertia ixx="0.0005" ixy="0.0" ixz="0.0" iyy="0.0005" iyz="0.0" izz="0.0005"/>
        </inertial>
    </link>

    <gazebo reference="caster_wheel">
        <material>Gazebo/Black</material>
        <mu1 value="0.001"/>
        <mu2 value="0.001"/>
    </gazebo>

</robot>